<?xml version="1.0" encoding="utf-8"?>
<!-- =================================================================================== -->
<!-- |    This document was autogenerated by xacro from spot.urdf.xacro                | -->
<!-- |    EDITING THIS FILE BY HAND IS NOT RECOMMENDED                                 | -->
<!-- =================================================================================== -->
<robot name="spot">
  <material name="yellow">
    <color rgba="0.92 0.83 0.0 1"/>
  </material>
  <material name="black">
    <color rgba="0.1 0.1 0.1 1"/>
  </material>
  <material name="grey">
    <color rgba="0.6 0.6 0.6 1"/>
  </material>
  <!-- Robot description -->
  <!-- Links -->
  <link name="base_footprint"/>
  <link name="base_link">
    <visual>
      <origin rpy="0 0 0" xyz="-0.045 -0.060 -0.015"/>
      <geometry>
        <mesh filename="stl/mainbody.stl" scale="0.001 0.001 0.001"/>
      </geometry>
      <material name="black"/>
    </visual>
    <collision>
      <origin rpy="0 0 0" xyz="0 0 0"/>
      <geometry>
        <box size="0.14 0.11 0.07"/>
      </geometry>
    </collision>
    <inertial>
      <mass value="2.8"/>
      <origin rpy="0 0 0" xyz="0 0 0"/>
      <!-- Inertial Axes -->
      <inertia ixx="0.00571666666667" ixy="0" ixz="0" iyx="0" iyy="0.00571666666667" iyz="0" izx="0" izy="0" izz="0.00739666666667"/>
    </inertial>
  </link>
  <link name="chassis_front_link">
    <visual>
      <origin rpy="0 0 0" xyz="-0.040 -0.060 -0.0140"/>
      <geometry>
        <mesh filename="stl/frontpart.stl" scale="0.001 0.001 0.001"/>
      </geometry>
      <material name="yellow"/>
    </visual>
    <collision>
      <origin rpy="0 0 0" xyz="-0.145 0 0"/>
      <geometry>
        <box size="0.058 0.11 0.07"/>
      </geometry>
    </collision>
    <inertial>
      <mass value="0.2"/>
      <origin rpy="0 0 0" xyz="-0.145 0 0"/>
      <!-- Inertial Axes -->
      <inertia ixx="0.000137733333333" ixy="0" ixz="0" iyx="0" iyy="0.000137733333333" iyz="0" izx="0" izy="0" izz="0.000257733333333"/>
    </inertial>
  </link>
  <link name="chassis_rear_link">
    <visual>
      <origin rpy="0 0 0" xyz="-0.040 -0.060 -0.0140"/>
      <geometry>
        <mesh filename="stl/backpart.stl" scale="0.001 0.001 0.001"/>
      </geometry>
      <material name="yellow"/>
    </visual>
    <collision>
      <origin rpy="0 0 0" xyz="0.135 0 0"/>
      <geometry>
        <box size="0.04 0.11 0.07"/>
      </geometry>
    </collision>
    <inertial>
      <mass value="0.2"/>
      <origin rpy="0 0 0" xyz="0.135 0 0"/>
      <!-- Inertial Axes -->
      <inertia ixx="0.000108333333333" ixy="0" ixz="0" iyx="0" iyy="0.000108333333333" iyz="0" izx="0" izy="0" izz="0.000228333333333"/>
    </inertial>
  </link>
  <link name="front_left_shoulder_link">
    <visual>
      <origin rpy="0 0 0" xyz="-0.135 -0.02 -0.01"/>
      <geometry>
        <mesh filename="stl/lshoulder.stl" scale="0.001 0.001 0.001"/>
      </geometry>
      <material name="black"/>
    </visual>
    <collision>
      <origin rpy="0 0 0" xyz="0 0 0"/>
      <geometry>
        <box size="0.044 0.038 0.07"/>
      </geometry>
    </collision>
    <inertial>
      <mass value="0.1"/>
      <origin rpy="0 0 0" xyz="0 0 0"/>
      <!-- Inertial Axes -->
      <inertia ixx="5.69666666667e-05" ixy="0" ixz="0" iyx="0" iyy="5.69666666667e-05" iyz="0" izx="0" izy="0" izz="2.81666666667e-05"/>
    </inertial>
  </link>
  <link name="front_left_leg_link_cover">
    <visual>
      <origin rpy="0 0 0" xyz="-0.125 0.04 -0.02"/>
      <geometry>
        <mesh filename="stl/larm_cover.stl" scale="0.001 0.001 0.001"/>
      </geometry>
      <material name="yellow"/>
    </visual>
    <collision>
      <origin rpy="0 0 0" xyz="0.0 0.0 -0.050"/>
      <geometry>
        <box size="0.028 0.036 0.12"/>
      </geometry>
    </collision>
    <inertial>
      <mass value="0.05"/>
      <origin rpy="0 0 0" xyz="0.0 0.0 -0.050"/>
      <!-- Inertial Axes -->
      <inertia ixx="6.32666666667e-05" ixy="0" ixz="0" iyx="0" iyy="6.32666666667e-05" iyz="0" izx="0" izy="0" izz="8.66666666667e-06"/>
    </inertial>
  </link>
  <link name="front_left_leg_link">
    <visual>
      <origin rpy="0 0 0" xyz="-0.125 0.04 -0.02"/>
      <geometry>
        <mesh filename="stl/larm.stl" scale="0.001 0.001 0.001"/>
      </geometry>
      <material name="black"/>
    </visual>
    <collision>
      <origin rpy="0 0 0" xyz="0.0 0.0 -0.050"/>
      <geometry>
        <box size="0.028 0.036 0.12"/>
      </geometry>
    </collision>
    <inertial>
      <mass value="0.15"/>
      <origin rpy="0 0 0" xyz="0.0 0.0 -0.050"/>
      <!-- Inertial Axes -->
      <inertia ixx="0.0001898" ixy="0" ixz="0" iyx="0" iyy="0.0001898" iyz="0" izx="0" izy="0" izz="2.6e-05"/>
    </inertial>
  </link>
  <link name="front_left_foot_link">
    <visual>
      <origin rpy="0 0 0" xyz="-0.120 0.04 0.1"/>
      <geometry>
        <mesh filename="stl/lfoot.stl" scale="0.001 0.001 0.001"/>
      </geometry>
      <material name="black"/>
    </visual>
    <collision>
      <origin rpy="0 0 0" xyz="0.0 0.0 -0.050"/>
      <geometry>
        <box size="0.026 0.02 0.115"/>
      </geometry>
    </collision>
    <inertial>
      <mass value="0.1"/>
      <origin rpy="0 0 0" xyz="0.0 0.0 -0.050"/>
      <!-- Inertial Axes -->
      <inertia ixx="0.000115841666667" ixy="0" ixz="0" iyx="0" iyy="0.000115841666667" iyz="0" izx="0" izy="0" izz="8.96666666667e-06"/>
    </inertial>
  </link>
  <link name="front_left_toe_link">
    <visual>
      <origin rpy="0 -0.40010 0" xyz="0 -0.01 0"/>
      <geometry>
        <mesh filename="stl/foot.stl" scale="0.001 0.001 0.001"/>
      </geometry>
      <material name="grey"/>
    </visual>
    <collision>
      <origin rpy="0 -0.40010 0" xyz="0 0 0"/>
      <geometry>
        <sphere radius="0.02"/>
      </geometry>
    </collision>
    <inertial>
      <mass value="0.05"/>
      <origin rpy="0 0 0" xyz="0 0 0"/>
      <!-- Inertial Axes -->
      <inertia ixx="3.33333333333e-06" ixy="0" ixz="0" iyx="0" iyy="3.33333333333e-06" iyz="0" izx="0" izy="0" izz="3.33333333333e-06"/>
    </inertial>
  </link>
  <link name="front_right_shoulder_link">
    <visual>
      <origin rpy="0 0 0" xyz="-0.135 -0.09 -0.01"/>
      <geometry>
        <mesh filename="stl/rshoulder.stl" scale="0.001 0.001 0.001"/>
      </geometry>
      <material name="black"/>
    </visual>
    <collision>
      <origin rpy="0 0 0" xyz="0 0 0"/>
      <geometry>
        <box size="0.044 0.038 0.07"/>
      </geometry>
    </collision>
    <inertial>
      <mass value="0.1"/>
      <origin rpy="0 0 0" xyz="0 0 0"/>
      <!-- Inertial Axes -->
      <inertia ixx="5.69666666667e-05" ixy="0" ixz="0" iyx="0" iyy="5.69666666667e-05" iyz="0" izx="0" izy="0" izz="2.81666666667e-05"/>
    </inertial>
  </link>
  <link name="front_right_leg_link_cover">
    <visual>
      <origin rpy="0 0 0" xyz="-0.125 -0.15 -0.02"/>
      <geometry>
        <mesh filename="stl/rarm_cover.stl" scale="0.001 0.001 0.001"/>
      </geometry>
      <material name="yellow"/>
    </visual>
    <collision>
      <origin rpy="0 0 0" xyz="0.0 0.0 -0.050"/>
      <geometry>
        <box size="0.028 0.036 0.12"/>
      </geometry>
    </collision>
    <inertial>
      <mass value="0.05"/>
      <origin rpy="0 0 0" xyz="0.0 0.0 -0.050"/>
      <!-- Inertial Axes -->
      <inertia ixx="6.32666666667e-05" ixy="0" ixz="0" iyx="0" iyy="6.32666666667e-05" iyz="0" izx="0" izy="0" izz="8.66666666667e-06"/>
    </inertial>
  </link>
  <link name="front_right_leg_link">
    <visual>
      <origin rpy="0 0 0" xyz="-0.125 -0.15 -0.02"/>
      <geometry>
        <mesh filename="stl/rarm.stl" scale="0.001 0.001 0.001"/>
      </geometry>
      <material name="black"/>
    </visual>
    <collision>
      <origin rpy="0 0 0" xyz="0.0 0.0 -0.050"/>
      <geometry>
        <box size="0.028 0.036 0.12"/>
      </geometry>
    </collision>
    <inertial>
      <mass value="0.15"/>
      <origin rpy="0 0 0" xyz="0.0 0.0 -0.050"/>
      <!-- Inertial Axes -->
      <inertia ixx="0.0001898" ixy="0" ixz="0" iyx="0" iyy="0.0001898" iyz="0" izx="0" izy="0" izz="2.6e-05"/>
    </inertial>
  </link>
  <link name="front_right_foot_link">
    <visual>
      <origin rpy="0 0 0" xyz="-0.120 -0.15 0.1"/>
      <geometry>
        <mesh filename="stl/rfoot.stl" scale="0.001 0.001 0.001"/>
      </geometry>
      <material name="black"/>
    </visual>
    <collision>
      <origin rpy="0 0 0" xyz="0.0 0.0 -0.050"/>
      <geometry>
        <box size="0.026 0.02 0.115"/>
      </geometry>
    </collision>
    <inertial>
      <mass value="0.1"/>
      <origin rpy="0 0 0" xyz="0.0 0.0 -0.050"/>
      <!-- Inertial Axes -->
      <inertia ixx="0.000115841666667" ixy="0" ixz="0" iyx="0" iyy="0.000115841666667" iyz="0" izx="0" izy="0" izz="8.96666666667e-06"/>
    </inertial>
  </link>
  <link name="front_right_toe_link">
    <visual>
      <origin rpy="0 -0.40010 0" xyz="0 -0.01 0"/>
      <geometry>
        <mesh filename="stl/foot.stl" scale="0.001 0.001 0.001"/>
      </geometry>
      <material name="grey"/>
    </visual>
    <collision>
      <origin rpy="0 -0.40010 0" xyz="0 0 0"/>
      <geometry>
        <sphere radius="0.02"/>
      </geometry>
    </collision>
    <inertial>
      <mass value="0.05"/>
      <origin rpy="0 0 0" xyz="0 0 0"/>
      <!-- Inertial Axes -->
      <inertia ixx="3.33333333333e-06" ixy="0" ixz="0" iyx="0" iyy="3.33333333333e-06" iyz="0" izx="0" izy="0" izz="3.33333333333e-06"/>
    </inertial>
  </link>
  <link name="rear_left_shoulder_link">
    <visual>
      <origin rpy="0 0 0" xyz="-0.135 -0.02 -0.01"/>
      <geometry>
        <mesh filename="stl/lshoulder.stl" scale="0.001 0.001 0.001"/>
      </geometry>
      <material name="black"/>
    </visual>
    <collision>
      <origin rpy="0 0 0" xyz="0 0 0"/>
      <geometry>
        <box size="0.044 0.038 0.07"/>
      </geometry>
    </collision>
    <inertial>
      <mass value="0.1"/>
      <origin rpy="0 0 0" xyz="0 0 0"/>
      <!-- Inertial Axes -->
      <inertia ixx="5.69666666667e-05" ixy="0" ixz="0" iyx="0" iyy="5.69666666667e-05" iyz="0" izx="0" izy="0" izz="2.81666666667e-05"/>
    </inertial>
  </link>
  <link name="rear_left_leg_link_cover">
    <visual>
      <origin rpy="0 0 0" xyz="-0.125 0.04 -0.02"/>
      <geometry>
        <mesh filename="stl/larm_cover.stl" scale="0.001 0.001 0.001"/>
      </geometry>
      <material name="yellow"/>
    </visual>
    <collision>
      <origin rpy="0 0 0" xyz="0.0 0.0 -0.050"/>
      <geometry>
        <box size="0.028 0.036 0.12"/>
      </geometry>
    </collision>
    <inertial>
      <mass value="0.05"/>
      <origin rpy="0 0 0" xyz="0.0 0.0 -0.050"/>
      <!-- Inertial Axes -->
      <inertia ixx="6.32666666667e-05" ixy="0" ixz="0" iyx="0" iyy="6.32666666667e-05" iyz="0" izx="0" izy="0" izz="8.66666666667e-06"/>
    </inertial>
  </link>
  <link name="rear_left_leg_link">
    <visual>
      <origin rpy="0 0 0" xyz="-0.125 0.04 -0.02"/>
      <geometry>
        <mesh filename="stl/larm.stl" scale="0.001 0.001 0.001"/>
      </geometry>
      <material name="black"/>
    </visual>
    <collision>
      <origin rpy="0 0 0" xyz="0.0 0.0 -0.050"/>
      <geometry>
        <box size="0.028 0.036 0.12"/>
      </geometry>
    </collision>
    <inertial>
      <mass value="0.15"/>
      <origin rpy="0 0 0" xyz="0.0 0.0 -0.050"/>
      <!-- Inertial Axes -->
      <inertia ixx="0.0001898" ixy="0" ixz="0" iyx="0" iyy="0.0001898" iyz="0" izx="0" izy="0" izz="2.6e-05"/>
    </inertial>
  </link>
  <link name="rear_left_foot_link">
    <visual>
      <origin rpy="0 0 0" xyz="-0.120 0.04 0.1"/>
      <geometry>
        <mesh filename="stl/lfoot.stl" scale="0.001 0.001 0.001"/>
      </geometry>
      <material name="black"/>
    </visual>
    <collision>
      <origin rpy="0 0 0" xyz="0.0 0.0 -0.050"/>
      <geometry>
        <box size="0.026 0.02 0.115"/>
      </geometry>
    </collision>
    <inertial>
      <mass value="0.1"/>
      <origin rpy="0 0 0" xyz="0.0 0.0 -0.050"/>
      <!-- Inertial Axes -->
      <inertia ixx="0.000115841666667" ixy="0" ixz="0" iyx="0" iyy="0.000115841666667" iyz="0" izx="0" izy="0" izz="8.96666666667e-06"/>
    </inertial>
  </link>
  <link name="rear_left_toe_link">
    <visual>
      <origin rpy="0 -0.40010 0" xyz="0 -0.01 0"/>
      <geometry>
        <mesh filename="stl/foot.stl" scale="0.001 0.001 0.001"/>
      </geometry>
      <material name="grey"/>
    </visual>
    <collision>
      <origin rpy="0 -0.40010 0" xyz="0 0 0"/>
      <geometry>
        <sphere radius="0.02"/>
      </geometry>
    </collision>
    <inertial>
      <mass value="0.05"/>
      <origin rpy="0 0 0" xyz="0 0 0"/>
      <!-- Inertial Axes -->
      <inertia ixx="3.33333333333e-06" ixy="0" ixz="0" iyx="0" iyy="3.33333333333e-06" iyz="0" izx="0" izy="0" izz="3.33333333333e-06"/>
    </inertial>
  </link>
  <link name="rear_right_shoulder_link">
    <visual>
      <origin rpy="0 0 0" xyz="-0.135 -0.09 -0.01"/>
      <geometry>
        <mesh filename="stl/rshoulder.stl" scale="0.001 0.001 0.001"/>
      </geometry>
      <material name="black"/>
    </visual>
    <collision>
      <origin rpy="0 0 0" xyz="0 0 0"/>
      <geometry>
        <box size="0.044 0.038 0.07"/>
      </geometry>
    </collision>
    <inertial>
      <mass value="0.1"/>
      <origin rpy="0 0 0" xyz="0 0 0"/>
      <!-- Inertial Axes -->
      <inertia ixx="5.69666666667e-05" ixy="0" ixz="0" iyx="0" iyy="5.69666666667e-05" iyz="0" izx="0" izy="0" izz="2.81666666667e-05"/>
    </inertial>
  </link>
  <link name="rear_right_leg_link_cover">
    <visual>
      <origin rpy="0 0 0" xyz="-0.125 -0.15 -0.02"/>
      <geometry>
        <mesh filename="stl/rarm_cover.stl" scale="0.001 0.001 0.001"/>
      </geometry>
      <material name="yellow"/>
    </visual>
    <collision>
      <origin rpy="0 0 0" xyz="0.0 0.0 -0.050"/>
      <geometry>
        <box size="0.028 0.036 0.12"/>
      </geometry>
    </collision>
    <inertial>
      <mass value="0.05"/>
      <origin rpy="0 0 0" xyz="0.0 0.0 -0.050"/>
      <!-- Inertial Axes -->
      <inertia ixx="6.32666666667e-05" ixy="0" ixz="0" iyx="0" iyy="6.32666666667e-05" iyz="0" izx="0" izy="0" izz="8.66666666667e-06"/>
    </inertial>
  </link>
  <link name="rear_right_leg_link">
    <visual>
      <origin rpy="0 0 0" xyz="-0.125 -0.15 -0.02"/>
      <geometry>
        <mesh filename="stl/rarm.stl" scale="0.001 0.001 0.001"/>
      </geometry>
      <material name="black"/>
    </visual>
    <collision>
      <origin rpy="0 0 0" xyz="0.0 0.0 -0.050"/>
      <geometry>
        <box size="0.028 0.036 0.12"/>
      </geometry>
    </collision>
    <inertial>
      <mass value="0.15"/>
      <origin rpy="0 0 0" xyz="0.0 0.0 -0.050"/>
      <!-- Inertial Axes -->
      <inertia ixx="0.0001898" ixy="0" ixz="0" iyx="0" iyy="0.0001898" iyz="0" izx="0" izy="0" izz="2.6e-05"/>
    </inertial>
  </link>
  <link name="rear_right_foot_link">
    <visual>
      <origin rpy="0 0 0" xyz="-0.120 -0.15 0.1"/>
      <geometry>
        <mesh filename="stl/rfoot.stl" scale="0.001 0.001 0.001"/>
      </geometry>
      <material name="black"/>
    </visual>
    <collision>
      <origin rpy="0 0 0" xyz="0.0 0.0 -0.050"/>
      <geometry>
        <box size="0.026 0.02 0.115"/>
      </geometry>
    </collision>
    <inertial>
      <mass value="0.1"/>
      <origin rpy="0 0 0" xyz="0.0 0.0 -0.050"/>
      <!-- Inertial Axes -->
      <inertia ixx="0.000115841666667" ixy="0" ixz="0" iyx="0" iyy="0.000115841666667" iyz="0" izx="0" izy="0" izz="8.96666666667e-06"/>
    </inertial>
  </link>
  <link name="rear_right_toe_link">
    <visual>
      <origin rpy="0 -0.40010 0" xyz="0 -0.01 0"/>
      <geometry>
        <mesh filename="stl/foot.stl" scale="0.001 0.001 0.001"/>
      </geometry>
      <material name="grey"/>
    </visual>
    <collision>
      <origin rpy="0 -0.40010 0" xyz="0 0 0"/>
      <geometry>
        <sphere radius="0.02"/>
      </geometry>
    </collision>
    <inertial>
      <mass value="0.05"/>
      <origin rpy="0 0 0" xyz="0 0 0"/>
      <!-- Inertial Axes -->
      <inertia ixx="3.33333333333e-06" ixy="0" ixz="0" iyx="0" iyy="3.33333333333e-06" iyz="0" izx="0" izy="0" izz="3.33333333333e-06"/>
    </inertial>
  </link>
  <joint name="base_base" type="fixed">
    <origin rpy="0 0 0" xyz="0 0 0"/>
    <parent link="base_footprint"/>
    <child link="base_link"/>
  </joint>
  <joint name="chassis_base_front" type="fixed">
    <origin rpy="0 0 0" xyz="0 0 0"/>
    <parent link="base_link"/>
    <child link="chassis_front_link"/>
  </joint>
  <joint name="chassis_base_rear" type="fixed">
    <origin rpy="0 0 0" xyz="0 0 0"/>
    <parent link="base_link"/>
    <child link="chassis_rear_link"/>
  </joint>
  <joint name="motor_front_left_shoulder" type="revolute">
    <axis xyz="1 0 0"/>
    <origin rpy="0 0 0" xyz="-0.093 -0.036 0"/>
    <parent link="base_link"/>
    <child link="front_left_shoulder_link"/>
    <limit effort="3.53" lower="-0.548" upper="0.548" velocity="9.52"/>
    <joint_properties damping="0.5" friction="0.5"/>
  </joint>
  <transmission name="tran0">
    <type>transmission_interface/SimpleTransmission</type>
    <joint name="motor_front_left_shoulder">
      <hardwareInterface>hardware_interface/EffortJointInterface</hardwareInterface>
    </joint>
    <actuator name="motor0">
      <mechanicalReduction>1</mechanicalReduction>
    </actuator>
  </transmission>
  <joint name="motor_front_left_leg" type="revolute">
    <axis xyz="0 1 0"/>
    <origin rpy="0 0 0" xyz="0 -0.052 0"/>
    <parent link="front_left_shoulder_link"/>
    <child link="front_left_leg_link"/>
    <limit effort="3.53" lower="-2.17" upper="0.97" velocity="9.52"/>
    <joint_properties damping="0.5" friction="0.5"/>
  </joint>
  <transmission name="tran0">
    <type>transmission_interface/SimpleTransmission</type>
    <joint name="motor_front_left_leg">
      <hardwareInterface>hardware_interface/EffortJointInterface</hardwareInterface>
    </joint>
    <actuator name="motor0">
      <mechanicalReduction>1</mechanicalReduction>
    </actuator>
  </transmission>
  <joint name="front_left_leg_cover_joint" type="fixed">
    <origin rpy="0 0 0" xyz="0 0 0"/>
    <parent link="front_left_leg_link"/>
    <child link="front_left_leg_link_cover"/>
  </joint>
  <joint name="foot_motor_front_left" type="revolute">
    <axis xyz="0 1 0"/>
    <origin rpy="0 0 0" xyz="-0.01 0 -0.12"/>
    <parent link="front_left_leg_link"/>
    <child link="front_left_foot_link"/>
    <limit effort="3.53" lower="-0.1" upper="2.59" velocity="9.52"/>
    <joint_properties damping="0.5" friction="0.5"/>
  </joint>
  <transmission name="tran0">
    <type>transmission_interface/SimpleTransmission</type>
    <joint name="foot_motor_front_left">
      <hardwareInterface>hardware_interface/EffortJointInterface</hardwareInterface>
    </joint>
    <actuator name="motor0">
      <mechanicalReduction>1</mechanicalReduction>
    </actuator>
  </transmission>
  <joint name="front_left_toe" type="fixed">
    <origin rpy="0 0 0" xyz="0 0 -0.115"/>
    <parent link="front_left_foot_link"/>
    <child link="front_left_toe_link"/>
  </joint>
  <joint name="motor_front_right_shoulder" type="revolute">
    <axis xyz="1 0 0"/>
    <origin rpy="0 0 0" xyz="-0.093 0.036 0"/>
    <parent link="base_link"/>
    <child link="front_right_shoulder_link"/>
    <limit effort="3.53" lower="-0.548" upper="0.548" velocity="9.52"/>
    <joint_properties damping="0.5" friction="0.5"/>
  </joint>
  <transmission name="tran0">
    <type>transmission_interface/SimpleTransmission</type>
    <joint name="motor_front_right_shoulder">
      <hardwareInterface>hardware_interface/EffortJointInterface</hardwareInterface>
    </joint>
    <actuator name="motor0">
      <mechanicalReduction>1</mechanicalReduction>
    </actuator>
  </transmission>
  <joint name="motor_front_right_leg" type="revolute">
    <axis xyz="0 1 0"/>
    <origin rpy="0 0 0" xyz="0 0.052 0"/>
    <parent link="front_right_shoulder_link"/>
    <child link="front_right_leg_link"/>
    <limit effort="3.53" lower="-2.17" upper="0.97" velocity="9.52"/>
    <joint_properties damping="0.5" friction="0.5"/>
  </joint>
  <transmission name="tran0">
    <type>transmission_interface/SimpleTransmission</type>
    <joint name="motor_front_right_leg">
      <hardwareInterface>hardware_interface/EffortJointInterface</hardwareInterface>
    </joint>
    <actuator name="motor0">
      <mechanicalReduction>1</mechanicalReduction>
    </actuator>
  </transmission>
  <joint name="front_right_leg_cover_joint" type="fixed">
    <origin rpy="0 0 0" xyz="0 0 0"/>
    <parent link="front_right_leg_link"/>
    <child link="front_right_leg_link_cover"/>
  </joint>
  <joint name="foot_motor_front_right" type="revolute">
    <axis xyz="0 1 0"/>
    <origin rpy="0 0 0" xyz="-0.01 0 -0.12"/>
    <parent link="front_right_leg_link"/>
    <child link="front_right_foot_link"/>
    <limit effort="3.53" lower="-0.1" upper="2.59" velocity="9.52"/>
    <joint_properties damping="0.5" friction="0.5"/>
  </joint>
  <transmission name="tran0">
    <type>transmission_interface/SimpleTransmission</type>
    <joint name="foot_motor_front_right">
      <hardwareInterface>hardware_interface/EffortJointInterface</hardwareInterface>
    </joint>
    <actuator name="motor0">
      <mechanicalReduction>1</mechanicalReduction>
    </actuator>
  </transmission>
  <joint name="front_right_toe" type="fixed">
    <origin rpy="0 0 0" xyz="0 0 -0.115"/>
    <parent link="front_right_foot_link"/>
    <child link="front_right_toe_link"/>
  </joint>
  <joint name="motor_rear_left_shoulder" type="revolute">
    <axis xyz="1 0 0"/>
    <origin rpy="0 0 0" xyz="0.093 -0.036 0"/>
    <parent link="base_link"/>
    <child link="rear_left_shoulder_link"/>
    <limit effort="3.53" lower="-0.548" upper="0.548" velocity="9.52"/>
    <joint_properties damping="0.5" friction="0.5"/>
  </joint>
  <transmission name="tran0">
    <type>transmission_interface/SimpleTransmission</type>
    <joint name="motor_rear_left_shoulder">
      <hardwareInterface>hardware_interface/EffortJointInterface</hardwareInterface>
    </joint>
    <actuator name="motor0">
      <mechanicalReduction>1</mechanicalReduction>
    </actuator>
  </transmission>
  <joint name="motor_rear_left_leg" type="revolute">
    <axis xyz="0 1 0"/>
    <origin rpy="0 0 0" xyz="0 -0.052 0"/>
    <parent link="rear_left_shoulder_link"/>
    <child link="rear_left_leg_link"/>
    <limit effort="3.53" lower="-2.17" upper="0.97" velocity="9.52"/>
    <joint_properties damping="0.5" friction="0.5"/>
  </joint>
  <transmission name="tran0">
    <type>transmission_interface/SimpleTransmission</type>
    <joint name="motor_rear_left_leg">
      <hardwareInterface>hardware_interface/EffortJointInterface</hardwareInterface>
    </joint>
    <actuator name="motor0">
      <mechanicalReduction>1</mechanicalReduction>
    </actuator>
  </transmission>
  <joint name="rear_left_leg_cover_joint" type="fixed">
    <origin rpy="0 0 0" xyz="0 0 0"/>
    <parent link="rear_left_leg_link"/>
    <child link="rear_left_leg_link_cover"/>
  </joint>
  <joint name="foot_motor_rear_left" type="revolute">
    <axis xyz="0 1 0"/>
    <origin rpy="0 0 0" xyz="-0.01 0 -0.12"/>
    <parent link="rear_left_leg_link"/>
    <child link="rear_left_foot_link"/>
    <limit effort="3.53" lower="-0.1" upper="2.59" velocity="9.52"/>
    <joint_properties damping="0.5" friction="0.5"/>
  </joint>
  <transmission name="tran0">
    <type>transmission_interface/SimpleTransmission</type>
    <joint name="foot_motor_rear_left">
      <hardwareInterface>hardware_interface/EffortJointInterface</hardwareInterface>
    </joint>
    <actuator name="motor0">
      <mechanicalReduction>1</mechanicalReduction>
    </actuator>
  </transmission>
  <joint name="rear_left_toe" type="fixed">
    <origin rpy="0 0 0" xyz="0 0 -0.115"/>
    <parent link="rear_left_foot_link"/>
    <child link="rear_left_toe_link"/>
  </joint>
  <joint name="motor_rear_right_shoulder" type="revolute">
    <axis xyz="1 0 0"/>
    <origin rpy="0 0 0" xyz="0.093 0.036 0"/>
    <parent link="base_link"/>
    <child link="rear_right_shoulder_link"/>
    <limit effort="3.53" lower="-0.548" upper="0.548" velocity="9.52"/>
    <joint_properties damping="0.5" friction="0.5"/>
  </joint>
  <transmission name="tran0">
    <type>transmission_interface/SimpleTransmission</type>
    <joint name="motor_rear_right_shoulder">
      <hardwareInterface>hardware_interface/EffortJointInterface</hardwareInterface>
    </joint>
    <actuator name="motor0">
      <mechanicalReduction>1</mechanicalReduction>
    </actuator>
  </transmission>
  <joint name="motor_rear_right_leg" type="revolute">
    <axis xyz="0 1 0"/>
    <origin rpy="0 0 0" xyz="0 0.052 0"/>
    <parent link="rear_right_shoulder_link"/>
    <child link="rear_right_leg_link"/>
    <limit effort="3.53" lower="-2.17" upper="0.97" velocity="9.52"/>
    <joint_properties damping="0.5" friction="0.5"/>
  </joint>
  <transmission name="tran0">
    <type>transmission_interface/SimpleTransmission</type>
    <joint name="motor_rear_right_leg">
      <hardwareInterface>hardware_interface/EffortJointInterface</hardwareInterface>
    </joint>
    <actuator name="motor0">
      <mechanicalReduction>1</mechanicalReduction>
    </actuator>
  </transmission>
  <joint name="rear_right_leg_cover_joint" type="fixed">
    <origin rpy="0 0 0" xyz="0 0 0"/>
    <parent link="rear_right_leg_link"/>
    <child link="rear_right_leg_link_cover"/>
  </joint>
  <joint name="foot_motor_rear_right" type="revolute">
    <axis xyz="0 1 0"/>
    <origin rpy="0 0 0" xyz="-0.01 0 -0.12"/>
    <parent link="rear_right_leg_link"/>
    <child link="rear_right_foot_link"/>
    <limit effort="3.53" lower="-0.1" upper="2.59" velocity="9.52"/>
    <joint_properties damping="0.5" friction="0.5"/>
  </joint>
  <transmission name="tran0">
    <type>transmission_interface/SimpleTransmission</type>
    <joint name="foot_motor_rear_right">
      <hardwareInterface>hardware_interface/EffortJointInterface</hardwareInterface>
    </joint>
    <actuator name="motor0">
      <mechanicalReduction>1</mechanicalReduction>
    </actuator>
  </transmission>
  <joint name="rear_right_toe" type="fixed">
    <origin rpy="0 0 0" xyz="0 0 -0.115"/>
    <parent link="rear_right_foot_link"/>
    <child link="rear_right_toe_link"/>
  </joint>
</robot>
