<?xml version="1.0" encoding="utf-8"?>
<!-- =================================================================================== -->
<!-- |    This document was autogenerated by xacro from spot.urdf.xacro                | -->
<!-- |    EDITING THIS FILE BY HAND IS NOT RECOMMENDED                                 | -->
<!-- =================================================================================== -->
<robot name="spot">
  <material name="orange">
    <color rgba="1.0 0.5 0.0 1"/>
  </material>
  <material name="black">
    <color rgba="0.1 0.1 0.1 1"/>
  </material>
  <material name="grey">
    <color rgba="0.6 0.6 0.6 1"/>
  </material>
  <!-- Robot description -->
  <!-- STATIC Links -->
  <link name="base_link">
    <visual>
      <origin rpy="0 0 1.57079632679" xyz="-0.16 0.035 -0.045"/>
      <geometry>
        <mesh filename="stl/OpenQuadruped/MAINBODY.stl" scale="1 1 1"/>
      </geometry>
      <material name="orange"/>
    </visual>
    <collision>
      <origin rpy="0 0 1.57079632679" xyz="0 0 0"/>
      <geometry>
        <box size="0.114 0.2 0.1"/>
      </geometry>
    </collision>
    <inertial>
      <mass value="1.20"/>
      <inertia ixx="100" ixy="0" ixz="0" iyy="100" iyz="0" izz="100"/>
      <origin rpy="0 0 0" xyz="0 0 0"/>
    </inertial>
  </link>
  <!-- m to mm -->
  <link name="battery">
    <visual>
      <origin rpy="0 0 1.57079632679" xyz="-0.15 0.035 -0.022"/>
      <geometry>
        <mesh filename="stl/OpenQuadruped/Battery.stl" scale="1 1 1"/>
      </geometry>
      <material name="black"/>
    </visual>
    <collision>
      <origin rpy="0 0 1.57079632679" xyz="0 0 0"/>
      <geometry>
        <box size="0.048 0.145 0.026"/>
      </geometry>
    </collision>
    <inertial>
      <mass value="0.4"/>
      <origin rpy="0 0 0" xyz="0 0 0"/>
      <!-- Inertial Axes -->
      <inertia ixx="0.000723366666667" ixy="0" ixz="0" iyx="0" iyy="9.93333333333e-05" iyz="0" izx="0" izy="0" izz="0.000777633333333"/>
    </inertial>
  </link>
  <!-- m to mm -->
  <link name="chassis_left">
    <visual>
      <origin rpy="0 1.57079632679 -1.57079632679" xyz="0.016 0.003 0"/>
      <geometry>
        <mesh filename="stl/OpenQuadruped/Chassis_Left_Side.stl" scale="1 1 1"/>
      </geometry>
      <material name="black"/>
    </visual>
    <collision>
      <origin rpy="0 1.57079632679 -1.57079632679" xyz="0 0 0"/>
      <geometry>
        <box size="0.06 0.15 0.006"/>
      </geometry>
    </collision>
    <inertial>
      <mass value="0.0001"/>
      <origin rpy="0 0 0" xyz="0 0 0"/>
      <!-- Inertial Axes -->
      <inertia ixx="0" ixy="0" ixz="0" iyx="0" iyy="0" iyz="0" izx="0" izy="0" izz="0"/>
    </inertial>
  </link>
  <!-- m to mm -->
  <link name="chassis_right">
    <visual>
      <origin rpy="0 1.57079632679 1.57079632679" xyz="-0.016 -0.003 0"/>
      <geometry>
        <mesh filename="stl/OpenQuadruped/Chassis_Right_Side.stl" scale="1 1 1"/>
      </geometry>
      <material name="black"/>
    </visual>
    <collision>
      <origin rpy="0 1.57079632679 1.57079632679" xyz="0 0 0"/>
      <geometry>
        <box size="0.06 0.15 0.006"/>
      </geometry>
    </collision>
    <inertial>
      <mass value="0.0001"/>
      <origin rpy="0 0 0" xyz="0 0 0"/>
      <!-- Inertial Axes -->
      <inertia ixx="0" ixy="0" ixz="0" iyx="0" iyy="0" iyz="0" izx="0" izy="0" izz="0"/>
    </inertial>
  </link>
  <!-- m to mm -->
  <link name="front">
    <visual>
      <origin rpy="0 0 1.57079632679" xyz="-0.16 0.035 -0.045"/>
      <geometry>
        <mesh filename="stl/OpenQuadruped/Front.stl" scale="1 1 1"/>
      </geometry>
      <material name="orange"/>
    </visual>
    <collision>
      <origin rpy="0 0 1.57079632679" xyz="0.16 0 0.006"/>
      <geometry>
        <box size="0.114 0.045 0.085"/>
      </geometry>
    </collision>
    <inertial>
      <mass value="0.025"/>
      <origin rpy="0 0 0" xyz="0 0 0"/>
      <!-- Inertial Axes -->
      <inertia ixx="100" ixy="0" ixz="0" iyy="100" iyz="0" izz="100"/>
    </inertial>
  </link>
  <!-- m to mm -->
  <link name="back">
    <visual>
      <origin rpy="0 0 1.57079632679" xyz="-0.16 0.035 -0.045"/>
      <geometry>
        <mesh filename="stl/OpenQuadruped/Back.stl" scale="1 1 1"/>
      </geometry>
      <material name="orange"/>
    </visual>
    <collision>
      <origin rpy="0 0 1.57079632679" xyz="-0.16 0 0.006"/>
      <geometry>
        <box size="0.114 0.075 0.085"/>
      </geometry>
    </collision>
    <inertial>
      <mass value="0.025"/>
      <origin rpy="0 0 0" xyz="0 0 0"/>
      <!-- Inertial Axes -->
      <inertia ixx="100" ixy="0" ixz="0" iyy="100" iyz="0" izz="100"/>
    </inertial>
  </link>
  <!-- m to mm -->
  <link name="front_bracket">
    <visual>
      <origin rpy="0 0 1.57079632679" xyz="-0.16 0.035 -0.045"/>
      <geometry>
        <mesh filename="stl/OpenQuadruped/Front_Bracket.stl" scale="1 1 1"/>
      </geometry>
      <material name="black"/>
    </visual>
    <collision>
      <origin rpy="0 0 1.57079632679" xyz="0.1 0 0"/>
      <geometry>
        <box size="0.025 0.075 0.085"/>
      </geometry>
    </collision>
    <inertial>
      <mass value="0.025"/>
      <origin rpy="0 0 0" xyz="0 0 0"/>
      <!-- Inertial Axes -->
      <inertia ixx="100" ixy="0" ixz="0" iyy="100" iyz="0" izz="100"/>
    </inertial>
  </link>
  <!-- m to mm -->
  <link name="back_bracket">
    <visual>
      <origin rpy="0 0 1.57079632679" xyz="-0.16 0.035 -0.045"/>
      <geometry>
        <mesh filename="stl/OpenQuadruped/Back_Bracket.stl" scale="1 1 1"/>
      </geometry>
      <material name="black"/>
    </visual>
    <collision>
      <origin rpy="0 0 1.57079632679" xyz="-0.1 0 0"/>
      <geometry>
        <box size="0.025 0.075 0.085"/>
      </geometry>
    </collision>
    <inertial>
      <mass value="0.025"/>
      <origin rpy="0 0 0" xyz="0 0 0"/>
      <!-- Inertial Axes -->
      <inertia ixx="100" ixy="0" ixz="0" iyy="100" iyz="0" izz="100"/>
    </inertial>
  </link>
  <!-- m to mm -->
  <link name="front_left_hip">
    <visual>
      <origin rpy="0 0 1.57079632679" xyz="-0.25 -0.0044 -0.067"/>
      <geometry>
        <mesh filename="stl/OpenQuadruped/LEFT_HIP.stl" scale="1 1 1"/>
      </geometry>
      <material name="black"/>
    </visual>
    <collision>
      <origin rpy="0 0 1.57079632679" xyz="0.015 0.01 -0.01"/>
      <geometry>
        <box size="0.05 0.065 0.065"/>
      </geometry>
    </collision>
    <inertial>
      <mass value="0.12"/>
      <origin rpy="0 0 0" xyz="0 0 0"/>
      <!-- Inertial Axes -->
      <inertia ixx="100" ixy="0" ixz="0" iyy="100" iyz="0" izz="100"/>
    </inertial>
  </link>
  <joint name="motor_front_left_hip" type="revolute">
    <axis xyz="1 0 0"/>
    <origin rpy="0 0 0" xyz="0.0915 0.0394 0.022"/>
    <parent link="front_bracket"/>
    <child link="front_left_hip"/>
    <limit effort="1000.0" lower="-1.04" upper="1.04" velocity="0.7"/>
    <joint_properties damping="0.0" friction="0.0"/>
  </joint>
  <link name="front_left_upper_leg">
    <visual>
      <origin rpy="0 0 1.57079632679" xyz="-0.252 -0.05 -0.055"/>
      <geometry>
        <mesh filename="stl/OpenQuadruped/LEFT_UPPER_LEG.stl" scale="1 1 1"/>
      </geometry>
      <material name="black"/>
    </visual>
    <collision>
      <origin rpy="0 0 1.57079632679" xyz="0 0.02 -0.05"/>
      <geometry>
        <box size="0.035 0.035 0.11"/>
      </geometry>
    </collision>
  </link>
  <joint name="motor_front_left_upper_leg" type="revolute">
    <axis xyz="0 1 0"/>
    <origin rpy="0 0 0" xyz="0.0015 0.045 -0.0087"/>
    <parent link="front_left_hip"/>
    <child link="front_left_upper_leg"/>
    <limit effort="1000.0" lower="-1.57079632679" upper="2.59" velocity="0.7"/>
    <joint_properties damping="0.0" friction="0.0"/>
  </joint>
  <link name="front_left_lower_leg">
    <visual>
      <origin rpy="0 0 1.57079632679" xyz="-0.247 -0.068 0.0535"/>
      <geometry>
        <mesh filename="stl/OpenQuadruped/LEFT_LOWER_LEG.stl" scale="1 1 1"/>
      </geometry>
      <material name="black"/>
    </visual>
    <collision>
      <origin rpy="0 0 1.57079632679" xyz="0 0 -0.06"/>
      <geometry>
        <box size="0.035 0.035 0.12"/>
      </geometry>
    </collision>
    <inertial>
      <mass value="0.1"/>
      <inertia ixx="100" ixy="0" ixz="0" iyy="100" iyz="0" izz="100"/>
    </inertial>
  </link>
  <joint name="motor_front_left_lower_leg" type="revolute">
    <axis xyz="0 1 0"/>
    <origin rpy="0 0 0" xyz="-0.005 0.018 -0.109"/>
    <parent link="front_left_upper_leg"/>
    <child link="front_left_lower_leg"/>
    <limit effort="1000.0" lower="-2.9" upper="1.57079632679" velocity="0.7"/>
    <joint_properties damping="0.0" friction="0.0"/>
  </joint>
  <link name="front_left_foot">
    <visual>
      <origin rpy="0 0 1.57079632679" xyz="-0.247 -0.068 0.18"/>
      <geometry>
        <mesh filename="stl/OpenQuadruped/LEFT_FOOT.stl" scale="1 1 1"/>
      </geometry>
      <material name="orange"/>
    </visual>
    <collision>
      <origin rpy="0 0 1.57079632679" xyz="-0.247 -0.068 0.18"/>
      <geometry>
        <mesh filename="stl/OpenQuadruped/LEFT_FOOT.stl" scale="1 1 1"/>
      </geometry>
      <contact_coefficients mu="10.1"/>
    </collision>
    <inertial>
      <mass value="0.005"/>
      <inertia ixx="100" ixy="0" ixz="0" iyy="100" iyz="0" izz="100"/>
    </inertial>
  </link>
  <joint name="front_left_leg_foot" type="fixed">
    <origin rpy="0 0 0" xyz="0 0 -0.1265"/>
    <parent link="front_left_lower_leg"/>
    <child link="front_left_foot"/>
  </joint>
  <link name="back_left_hip">
    <visual>
      <origin rpy="0 0 1.57079632679" xyz="-0.25 -0.0044 -0.067"/>
      <geometry>
        <mesh filename="stl/OpenQuadruped/LEFT_HIP.stl" scale="1 1 1"/>
      </geometry>
      <material name="black"/>
    </visual>
    <collision>
      <origin rpy="0 0 1.57079632679" xyz="0.015 0.01 -0.01"/>
      <geometry>
        <box size="0.05 0.065 0.065"/>
      </geometry>
    </collision>
    <inertial>
      <mass value="0.120"/>
      <inertia ixx="100" ixy="0" ixz="0" iyy="100" iyz="0" izz="100"/>
    </inertial>
  </link>
  <joint name="motor_back_left_hip" type="revolute">
    <axis xyz="1 0 0"/>
    <origin rpy="0 0 0" xyz="-0.1365 0.0394 0.022"/>
    <parent link="back_bracket"/>
    <child link="back_left_hip"/>
    <limit effort="1000.0" lower="-1.04" upper="1.04" velocity="0.7"/>
    <joint_properties damping="0.0" friction="0.0"/>
  </joint>
  <link name="back_left_upper_leg">
    <visual>
      <origin rpy="0 0 1.57079632679" xyz="-0.252 -0.05 -0.055"/>
      <geometry>
        <mesh filename="stl/OpenQuadruped/LEFT_UPPER_LEG.stl" scale="1 1 1"/>
      </geometry>
      <material name="black"/>
    </visual>
    <collision>
      <origin rpy="0 0 1.57079632679" xyz="0 0.02 -0.05"/>
      <geometry>
        <box size="0.035 0.035 0.11"/>
      </geometry>
    </collision>
  </link>
  <joint name="motor_back_left_upper_leg" type="revolute">
    <axis xyz="0 1 0"/>
    <origin rpy="0 0 0" xyz="0.0015 0.045 -0.0087"/>
    <parent link="back_left_hip"/>
    <child link="back_left_upper_leg"/>
    <limit effort="1000.0" lower="-1.57079632679" upper="2.59" velocity="0.7"/>
    <joint_properties damping="0.0" friction="0.0"/>
  </joint>
  <link name="back_left_lower_leg">
    <visual>
      <origin rpy="0 0 1.57079632679" xyz="-0.247 -0.068 0.0535"/>
      <geometry>
        <mesh filename="stl/OpenQuadruped/LEFT_LOWER_LEG.stl" scale="1 1 1"/>
      </geometry>
      <material name="black"/>
    </visual>
    <collision>
      <origin rpy="0 0 1.57079632679" xyz="0 0 -0.06"/>
      <geometry>
        <box size="0.035 0.035 0.12"/>
      </geometry>
    </collision>
    <inertial>
      <mass value="0.1"/>
      <inertia ixx="100" ixy="0" ixz="0" iyy="100" iyz="0" izz="100"/>
    </inertial>
  </link>
  <joint name="motor_back_left_lower_leg" type="revolute">
    <axis xyz="0 1 0"/>
    <origin rpy="0 0 0" xyz="-0.005 0.018 -0.109"/>
    <parent link="back_left_upper_leg"/>
    <child link="back_left_lower_leg"/>
    <limit effort="1000.0" lower="-2.9" upper="1.57079632679" velocity="0.7"/>
    <joint_properties damping="0.0" friction="0.0"/>
  </joint>
  <link name="back_left_foot">
    <visual>
      <origin rpy="0 0 1.57079632679" xyz="-0.247 -0.068 0.18"/>
      <geometry>
        <mesh filename="stl/OpenQuadruped/LEFT_FOOT.stl" scale="1 1 1"/>
      </geometry>
      <material name="orange"/>
    </visual>
    <collision>
      <origin rpy="0 0 1.57079632679" xyz="-0.247 -0.068 0.18"/>
      <geometry>
        <mesh filename="stl/OpenQuadruped/LEFT_FOOT.stl" scale="1 1 1"/>
      </geometry>
      <contact_coefficients mu="10.1"/>
    </collision>
    <inertial>
      <mass value="0.005"/>
      <inertia ixx="100" ixy="0" ixz="0" iyy="100" iyz="0" izz="100"/>
    </inertial>
  </link>
  <joint name="back_left_leg_foot" type="fixed">
    <origin rpy="0 0 0" xyz="0 0 -0.1265"/>
    <parent link="back_left_lower_leg"/>
    <child link="back_left_foot"/>
  </joint>
  <link name="front_right_hip">
    <visual>
      <origin rpy="0 0 1.57079632679" xyz="-0.25 0.074 -0.067"/>
      <geometry>
        <mesh filename="stl/OpenQuadruped/RIGHT_HIP.stl" scale="1 1 1"/>
      </geometry>
      <material name="black"/>
    </visual>
    <collision>
      <origin rpy="0 0 1.57079632679" xyz="0.015 -0.01 -0.01"/>
      <geometry>
        <box size="0.05 0.065 0.065"/>
      </geometry>
    </collision>
    <inertial>
      <mass value="0.120"/>
      <inertia ixx="100" ixy="0" ixz="0" iyy="100" iyz="0" izz="100"/>
    </inertial>
  </link>
  <joint name="motor_front_right_hip" type="revolute">
    <axis xyz="1 0 0"/>
    <origin rpy="0 0 0" xyz="0.0915 -0.0394 0.022"/>
    <parent link="front_bracket"/>
    <child link="front_right_hip"/>
    <limit effort="1000.0" lower="-1.04" upper="1.04" velocity="0.7"/>
    <joint_properties damping="0.0" friction="0.0"/>
  </joint>
  <link name="front_right_upper_leg">
    <visual>
      <origin rpy="0 0 1.57079632679" xyz="-0.252 0.12 -0.055"/>
      <geometry>
        <mesh filename="stl/OpenQuadruped/RIGHT_UPPER_LEG.stl" scale="1 1 1"/>
      </geometry>
      <material name="black"/>
    </visual>
    <collision>
      <origin rpy="0 0 1.57079632679" xyz="0 -0.02 -0.05"/>
      <geometry>
        <box size="0.035 0.035 0.11"/>
      </geometry>
    </collision>
  </link>
  <joint name="motor_front_right_upper_leg" type="revolute">
    <axis xyz="0 1 0"/>
    <origin rpy="0 0 0" xyz="0.0015 -0.045 -0.0087"/>
    <parent link="front_right_hip"/>
    <child link="front_right_upper_leg"/>
    <limit effort="1000.0" lower="-1.57079632679" upper="2.59" velocity="0.7"/>
    <joint_properties damping="0.0" friction="0.0"/>
  </joint>
  <link name="front_right_lower_leg">
    <visual>
      <origin rpy="0 0 1.57079632679" xyz="-0.247 0.138 0.0535"/>
      <geometry>
        <mesh filename="stl/OpenQuadruped/RIGHT_LOWER_LEG.stl" scale="1 1 1"/>
      </geometry>
      <material name="black"/>
    </visual>
    <collision>
      <origin rpy="0 0 1.57079632679" xyz="0 0 -0.06"/>
      <geometry>
        <box size="0.035 0.035 0.12"/>
      </geometry>
    </collision>
    <inertial>
      <mass value="0.1"/>
      <inertia ixx="100" ixy="0" ixz="0" iyy="100" iyz="0" izz="100"/>
    </inertial>
  </link>
  <joint name="motor_front_right_lower_leg" type="revolute">
    <axis xyz="0 1 0"/>
    <origin rpy="0 0 0" xyz="-0.005 -0.018 -0.109"/>
    <parent link="front_right_upper_leg"/>
    <child link="front_right_lower_leg"/>
    <limit effort="1000.0" lower="-2.9" upper="1.57079632679" velocity="0.7"/>
    <joint_properties damping="0.0" friction="0.0"/>
  </joint>
  <link name="front_right_foot">
    <visual>
      <origin rpy="0 0 1.57079632679" xyz="-0.247 0.138 0.18"/>
      <geometry>
        <mesh filename="stl/OpenQuadruped/RIGHT_FOOT.stl" scale="1 1 1"/>
      </geometry>
      <material name="orange"/>
    </visual>
    <collision>
      <origin rpy="0 0 1.57079632679" xyz="-0.247 0.138 0.18"/>
      <geometry>
        <mesh filename="stl/OpenQuadruped/RIGHT_FOOT.stl" scale="1 1 1"/>
      </geometry>
      <contact_coefficients mu="10.1"/>
    </collision>
    <inertial>
      <mass value="0.005"/>
      <inertia ixx="100" ixy="0" ixz="0" iyy="100" iyz="0" izz="100"/>
    </inertial>
  </link>
  <joint name="front_right_leg_foot" type="fixed">
    <origin rpy="0 0 0" xyz="0 0 -0.1265"/>
    <parent link="front_right_lower_leg"/>
    <child link="front_right_foot"/>
  </joint>
  <link name="back_right_hip">
    <visual>
      <origin rpy="0 0 1.57079632679" xyz="-0.25 0.074 -0.067"/>
      <geometry>
        <mesh filename="stl/OpenQuadruped/RIGHT_HIP.stl" scale="1 1 1"/>
      </geometry>
      <material name="black"/>
    </visual>
    <collision>
      <origin rpy="0 0 1.57079632679" xyz="0.015 -0.01 -0.01"/>
      <geometry>
        <box size="0.05 0.065 0.065"/>
      </geometry>
    </collision>
    <inertial>
      <mass value="0.120"/>
      <inertia ixx="100" ixy="0" ixz="0" iyy="100" iyz="0" izz="100"/>
    </inertial>
  </link>
  <joint name="motor_back_right_hip" type="revolute">
    <axis xyz="1 0 0"/>
    <origin rpy="0 0 0" xyz="-0.1365 -0.0394 0.022"/>
    <parent link="back_bracket"/>
    <child link="back_right_hip"/>
    <limit effort="1000.0" lower="-1.04" upper="1.04" velocity="0.7"/>
    <joint_properties damping="0.0" friction="0.0"/>
  </joint>
  <link name="back_right_upper_leg">
    <visual>
      <origin rpy="0 0 1.57079632679" xyz="-0.252 0.12 -0.055"/>
      <geometry>
        <mesh filename="stl/OpenQuadruped/RIGHT_UPPER_LEG.stl" scale="1 1 1"/>
      </geometry>
      <material name="black"/>
    </visual>
    <collision>
      <origin rpy="0 0 1.57079632679" xyz="0 -0.02 -0.05"/>
      <geometry>
        <box size="0.035 0.035 0.11"/>
      </geometry>
    </collision>
  </link>
  <joint name="motor_back_right_upper_leg" type="revolute">
    <axis xyz="0 1 0"/>
    <origin rpy="0 0 0" xyz="0.0015 -0.045 -0.0087"/>
    <parent link="back_right_hip"/>
    <child link="back_right_upper_leg"/>
    <limit effort="1000.0" lower="-1.57079632679" upper="2.59" velocity="0.7"/>
    <joint_properties damping="0.0" friction="0.0"/>
  </joint>
  <link name="back_right_lower_leg">
    <visual>
      <origin rpy="0 0 1.57079632679" xyz="-0.247 0.138 0.0535"/>
      <geometry>
        <mesh filename="stl/OpenQuadruped/RIGHT_LOWER_LEG.stl" scale="1 1 1"/>
      </geometry>
      <material name="black"/>
    </visual>
    <collision>
      <origin rpy="0 0 1.57079632679" xyz="0 0 -0.06"/>
      <geometry>
        <box size="0.035 0.035 0.12"/>
      </geometry>
    </collision>
    <inertial>
      <mass value="0.1"/>
      <inertia ixx="100" ixy="0" ixz="0" iyy="100" iyz="0" izz="100"/>
    </inertial>
  </link>
  <joint name="motor_back_right_lower_leg" type="revolute">
    <axis xyz="0 1 0"/>
    <origin rpy="0 0 0" xyz="-0.005 -0.018 -0.109"/>
    <parent link="back_right_upper_leg"/>
    <child link="back_right_lower_leg"/>
    <limit effort="1000.0" lower="-2.9" upper="1.57079632679" velocity="0.7"/>
    <joint_properties damping="0.0" friction="0.0"/>
  </joint>
  <link name="back_right_foot">
    <visual>
      <origin rpy="0 0 1.57079632679" xyz="-0.247 0.138 0.18"/>
      <geometry>
        <mesh filename="stl/OpenQuadruped/RIGHT_FOOT.stl" scale="1 1 1"/>
      </geometry>
      <material name="orange"/>
    </visual>
    <collision>
      <origin rpy="0 0 1.57079632679" xyz="-0.247 0.138 0.18"/>
      <geometry>
        <mesh filename="stl/OpenQuadruped/RIGHT_FOOT.stl" scale="1 1 1"/>
      </geometry>
      <contact_coefficients mu="10.1"/>
    </collision>
    <inertial>
      <mass value="0.005"/>
      <inertia ixx="100" ixy="0" ixz="0" iyy="100" iyz="0" izz="100"/>
    </inertial>
  </link>
  <joint name="back_right_leg_foot" type="fixed">
    <origin rpy="0 0 0" xyz="0 0 -0.1265"/>
    <parent link="back_right_lower_leg"/>
    <child link="back_right_foot"/>
  </joint>
  <joint name="base_battery" type="fixed">
    <origin rpy="0 0 0" xyz="-0.01 0 -0.0225"/>
    <parent link="base_link"/>
    <child link="battery"/>
  </joint>
  <joint name="base_left" type="fixed">
    <origin rpy="0 0 0" xyz="0.00 0.052 0"/>
    <parent link="base_link"/>
    <child link="chassis_left"/>
  </joint>
  <joint name="base_right" type="fixed">
    <origin rpy="0 0 0" xyz="0.00 -0.052 0"/>
    <parent link="base_link"/>
    <child link="chassis_right"/>
  </joint>
  <joint name="base_front" type="fixed">
    <origin rpy="0 0 0" xyz="0 0 0"/>
    <parent link="base_link"/>
    <child link="front"/>
  </joint>
  <joint name="base_back" type="fixed">
    <origin rpy="0 0 0" xyz="0 0 0"/>
    <parent link="base_link"/>
    <child link="back"/>
  </joint>
  <joint name="base_front_bracket" type="fixed">
    <origin rpy="0 0 0" xyz="0 0 0"/>
    <parent link="base_link"/>
    <child link="front_bracket"/>
  </joint>
  <joint name="base_back_bracket" type="fixed">
    <origin rpy="0 0 0" xyz="0 0 0"/>
    <parent link="base_link"/>
    <child link="back_bracket"/>
  </joint>
</robot>
